<?xml version="1.0"?>
<robot>
    <link name='hokuyo'>
      <inertial>
        <mass value="0.1"/>
        <origin xyz="0.0 0 0" rpy=" 0 0 0"/>
        <inertia ixx="1e-6" ixy="0" ixz="0" iyy="1e-6" iyz="0" izz="1e-6"/>
      </inertial>
      <collision name='hokuyo_collision'>
        <origin xyz="0.0 0 0" rpy=" 0 0 0"/>
        <geometry>
          <box size="0.1 0.1 0.1"/>
        </geometry>
      </collision>
      <visual name='hokuyo_visual'>
        <origin xyz="0.0 0 0" rpy=" 0 0 0"/>
        <geometry>
          <mesh filename="package://bresilla/meshes/hokuyo.dae"/>
        </geometry>
      </visual>
    </link>

    <joint name="hokuyo_joint" type="revolute">
      <origin xyz="0.65 0 0.02" rpy="0 0 0"/>
      <child link="hokuyo"/>
      <parent link="mounting_plate"/>
      <limit upper="6.28" lower="-6.28" effort="1000" velocity="1000.00"/>
    </joint>

    <gazebo reference="hokuyo">
      <sensor name="head_hokuyo_sensor" type="ray">
        <pose>0 0 0 0 0 0</pose>
        <visualize>true</visualize>
        <update_rate>30</update_rate>
        <ray>
          <scan>
            <horizontal>
              <samples>640</samples>
              <resolution>1</resolution>
              <min_angle>-2.26889</min_angle>
              <max_angle>2.268899</max_angle>
            </horizontal>
          </scan>
          <range>
            <min>0.30</min>
            <max>20</max>
            <resolution>0.01</resolution>
          </range>
        </ray>
        <plugin name="gazebo_ros_head_hokuyo_controller" filename="libgazebo_ros_laser.so">
          <topicName>/bresilla/laser/scan</topicName>
          <frameName>hokuyo</frameName>
        </plugin>
      </sensor>
    </gazebo>
</robot>